Workbook

Sheet April 2026
A1: NGO Month-End Checklist
A2: Finance Department | Prepared by: _______________ | Month: _______________ | Reviewed by: _______________
A4: # | B4: Section | C4: Checklist Item | D4: Status | E4: Completed By | F4: Notes | G4: Confirmed By | H4: Status
A5: Income (Statement of Activities) | G5: HOD
A6: 1 | B6: Income (Statement of Activities) | C6: Record and classify all grant income received by fund/restriction | D6: N/A | E6: Accountant | F6: Grant income from March 2026 (Historical Consulting) received in May 2026 | G6: HOD | H6: Pending
A7: 2 | B7: Income (Statement of Activities) | C7: Post donation and fundraising income, confirm against receipts | D7: Pending | E7: Accountant | G7: HOD | H7: Pending
A8: 3 | B8: Income (Statement of Activities) | C8: Accrue any earned but uninvoiced income (e.g. milestone-based grants) | D8: Pending | E8: Accountant | G8: HOD | H8: Pending
A9: 4 | B9: Income (Statement of Activities) | C9: Record interest income and any forex gains on foreign currency receipts | D9: Pending | E9: Accountant | G9: HOD | H9: Pending
A10: 5 | B10: Income (Statement of Activities) | C10: Reconcile income by programme/project code to grant agreements | D10: Pending | E10: Accountant | G10: HOD | H10: Pending
A11: 6 | B11: Income (Statement of Activities) | C11: Confirm restricted vs unrestricted income split is correctly coded | D11: Pending | E11: Accountant | G11: HOD | H11: Pending
A12: Expenditure (Statement of Activities) | G12: HOD
A13: 7 | B13: Expenditure (Statement of Activities) | C13: Ensure all invoices and payment vouchers are posted and approved | D13: Complete | E13: Accountant | G13: HOD | H13: Pending
A14: 8 | B14: Expenditure (Statement of Activities) | C14: Verify payroll and staff costs allocated correctly to programme/admin | D14: Pending | E14: Accountant | G14: HOD | H14: Pending
A15: 9 | B15: Expenditure (Statement of Activities) | C15: Post accruals for goods/services received but not yet invoiced | D15: Pending | E15: Accountant | G15: HOD | H15: Pending
A16: 10 | B16: Expenditure (Statement of Activities) | C16: Review prepayments and release appropriate portion to expense | D16: Pending | E16: Accountant | G16: HOD | H16: Pending
A17: 11 | B17: Expenditure (Statement of Activities) | C17: Confirm shared costs (rent, utilities) are apportioned across cost centres | D17: Pending | E17: Accountant | G17: HOD | H17: Pending
A18: 12 | B18: Expenditure (Statement of Activities) | C18: Check for duplicate payments or unapproved expenditure | D18: Pending | E18: Accountant | G18: HOD | H18: Pending
A19: 13 | B19: Expenditure (Statement of Activities) | C19: Compare expenditure to budget line items; document variances above 10% | D19: Pending | E19: Accountant | G19: HOD | H19: Pending
A20: 14 | B20: Expenditure (Statement of Activities) | C20: Check for accuracy in coding for each expenditure per grant | D20: Pending | E20: Accountant | G20: HOD | H20: Pending
A21: 15 | B21: Expenditure (Statement of Activities) | C21: Have you done an FX valuation | D21: Pending | E21: Accountant | G21: HOD | H21: Pending
A22: 16 | B22: Expenditure (Statement of Activities) | C22: Have you submitted payment vouchers for signing to Chao | D22: Pending | E22: Accountant | G22: HOD | H22: Pending
A23: Balance Sheet Items | G23: HOD
A24: 17 | B24: Balance Sheet Items | C24: Reconcile all bank accounts and confirm closing cash balances | D24: Pending | E24: Accountant | G24: HOD | H24: Pending
A25: 18 | B25: Balance Sheet Items | C25: Submit bank reconciliations to Chao for signature | D25: Pending | E25: Accountant | G25: HOD
A26: 18 | B26: Balance Sheet Items | C26: Update fixed asset register — additions, disposals, monthly depreciation | D26: Pending | E26: Accountant | G26: HOD | H26: Pending
A27: 19 | B27: Balance Sheet Items | C27: Confirm petty cash count matches petty cash ledger balance | D27: Pending | E27: Accountant | G27: HOD | H27: Pending
A28: 20 | B28: Balance Sheet Items | C28: Verify deferred income balance reflects unspent restricted grant funds | D28: Pending | E28: Accountant | G28: HOD | H28: Pending
A29: 21 | B29: Balance Sheet Items | C29: Review fund balances — restricted, unrestricted, designated | D29: Pending | E29: Accountant | G29: HOD | H29: Pending
A30: 22 | B30: Balance Sheet Items | C30: Prepare and review trial balance; confirm it is in balance | D30: Pending | E30: Accountant | G30: HOD | H30: Pending
A31: Advances | G31: HOD
A32: 23 | B32: Advances | C32: Print advances register and confirm all open balances per staff/partner | D32: Pending | E32: Accountant | G32: HOD | H32: Pending
A33: 24 | B33: Advances | C33: Follow up on all advances outstanding beyond the approved clearance period | D33: Pending | E33: Accountant | G33: HOD | H33: Pending
A34: 25 | B34: Advances | C34: Review and post retirement/liquidation documents submitted this month | D34: Pending | E34: Accountant | G34: HOD | H34: Pending
A35: 26 | B35: Advances | C35: Confirm no new advance issued to staff with an unretired prior advance | D35: Pending | E35: Accountant | G35: HOD | H35: Pending
A36: 27 | B36: Advances | C36: Reconcile advances to implementing partners against sub-grant agreements | D36: Pending | E36: Accountant | G36: HOD | H36: Pending
A37: 28 | B37: Advances | C37: Flag advances older than 90 days to management for escalation | D37: Pending | E37: Accountant | G37: HOD | H37: Pending
A38: 29 | B38: Advances | C38: Ensure advances ledger balance agrees to balance sheet advances line | D38: Pending | E38: Accountant | G38: HOD | H38: Pending
A39: Receivables | G39: HOD
A40: 30 | B40: Receivables | C40: Generate aged receivables report and review balances by donor/partner | D40: Pending | E40: Accountant | G40: HOD | H40: Pending
A41: 31 | B41: Receivables | C41: Follow up on overdue grant reimbursements and donor invoices | D41: Pending | E41: Accountant | G41: HOD | H41: Pending
...

Sheet July
A1: NGO Month-End Checklist
A2: Finance Department | Prepared by: ______Shadrack_________ | Month: _______July________ | Reviewed by: _______________
A4: # | B4: Section | C4: Checklist Item | D4: Status | E4: Completed By | F4: Notes | G4: Confirmed By | H4: Status
A5: Income (Statement of Activities) | G5: HOD
A6: 1 | B6: Income (Statement of Activities) | C6: Record and classify all grant income received by fund/restriction | D6: Complete | E6: Accountant | F6: No grant received | G6: HOD | H6: Complete
A7: 2 | B7: Income (Statement of Activities) | C7: Post donation and fundraising income, confirm against receipts | D7: Complete | E7: Accountant | F7: NO donation received | G7: HOD | H7: Complete
A8: 3 | B8: Income (Statement of Activities) | C8: Accrue any earned but uninvoiced income (e.g. milestone-based grants) | D8: Complete | E8: Accountant | G8: HOD | H8: Complete
A9: 4 | B9: Income (Statement of Activities) | C9: Record interest income and any forex gains on foreign currency receipts | D9: Complete | E9: Accountant | G9: HOD | H9: Complete
A10: 5 | B10: Income (Statement of Activities) | C10: Reconcile income by programme/project code to grant agreements | D10: Complete | E10: Accountant | G10: HOD | H10: Complete
A11: 6 | B11: Income (Statement of Activities) | C11: Confirm restricted vs unrestricted income split is correctly coded | D11: Complete | E11: Accountant | G11: HOD | H11: Complete
A12: Expenditure (Statement of Activities)
A13: 7 | B13: Expenditure (Statement of Activities) | C13: Ensure all invoices and payment vouchers are posted and approved | D13: Complete | E13: Accountant | G13: HOD | H13: Complete
A14: 8 | B14: Expenditure (Statement of Activities) | C14: Verify payroll and staff costs allocated correctly to programme/admin | D14: Complete | E14: Accountant | G14: HOD | H14: Complete
A15: 9 | B15: Expenditure (Statement of Activities) | C15: Post accruals for goods/services received but not yet invoiced | D15: N/A | E15: Accountant | G15: HOD | H15: Complete
A16: 10 | B16: Expenditure (Statement of Activities) | C16: Review prepayments and release appropriate portion to expense | D16: N/A | E16: Accountant | G16: HOD | H16: Complete
A17: 11 | B17: Expenditure (Statement of Activities) | C17: Confirm shared costs (rent, utilities) are apportioned across cost centres | D17: N/A | E17: Accountant | G17: HOD | H17: Complete
A18: 12 | B18: Expenditure (Statement of Activities) | C18: Check for duplicate payments or unapproved expenditure | D18: Complete | E18: Accountant | G18: HOD | H18: Complete
A19: 13 | B19: Expenditure (Statement of Activities) | C19: Compare expenditure to budget line items; document variances above 10% | D19: Pending | E19: Accountant | G19: HOD | H19: Complete
A20: 14 | B20: Expenditure (Statement of Activities) | C20: Check for accuracy in coding for each expenditure per grant | D20: Complete | E20: Accountant | G20: HOD | H20: Complete
A21: 15 | B21: Expenditure (Statement of Activities) | C21: Have you done an FX valuation | D21: Complete | E21: Accountant | G21: HOD | H21: Complete
A22: 16 | B22: Expenditure (Statement of Activities) | C22: Have you submitted payment vouchers for signing to Chao | D22: Complete | E22: Accountant | G22: HOD | H22: Complete
A23: Balance Sheet Items
A24: 17 | B24: Balance Sheet Items | C24: Reconcile all bank accounts and confirm closing cash balances | D24: Complete | E24: Accountant | G24: HOD | H24: Complete
A25: 18 | B25: Balance Sheet Items | C25: Submit bank reconciliations to Chao for signature | D25: Complete | E25: Accountant | G25: HOD | H25: Complete
A26: 18 | B26: Balance Sheet Items | C26: Update fixed asset register — additions, disposals, monthly depreciation | D26: Complete | E26: Accountant | G26: HOD | H26: Complete
A27: 19 | B27: Balance Sheet Items | C27: Confirm petty cash count matches petty cash ledger balance | D27: N/A | E27: Accountant | G27: HOD | H27: Complete
A28: 20 | B28: Balance Sheet Items | C28: Verify deferred income balance reflects unspent restricted grant funds | D28: N/A | E28: Accountant | G28: HOD | H28: Complete
A29: 21 | B29: Balance Sheet Items | C29: Review fund balances — restricted, unrestricted, designated | D29: Complete | E29: Accountant | G29: HOD | H29: Complete
A30: 22 | B30: Balance Sheet Items | C30: Prepare and review trial balance; confirm it is in balance | D30: Complete | E30: Accountant | G30: HOD | H30: Complete
A31: Advances
A32: 23 | B32: Advances | C32: Print advances register and confirm all open balances per staff/partner | D32: N/A | E32: Accountant | G32: HOD | H32: Complete
A33: 24 | B33: Advances | C33: Follow up on all advances outstanding beyond the approved clearance period | D33: Complete | E33: Accountant | G33: HOD | H33: Complete
A34: 25 | B34: Advances | C34: Review and post retirement/liquidation documents submitted this month | D34: N/A | E34: Accountant | G34: HOD | H34: Complete
A35: 26 | B35: Advances | C35: Confirm no new advance issued to staff with an unretired prior advance | D35: N/A | E35: Accountant | G35: HOD | H35: Complete
A36: 27 | B36: Advances | C36: Reconcile advances to implementing partners against sub-grant agreements | D36: Complete | E36: Accountant | G36: HOD | H36: Complete
A37: 28 | B37: Advances | C37: Flag advances older than 90 days to management for escalation | D37: Complete | E37: Accountant | G37: HOD | H37: Complete
A38: 29 | B38: Advances | C38: Ensure advances ledger balance agrees to balance sheet advances line | D38: Complete | E38: Accountant | G38: HOD | H38: Complete
A39: Receivables
A40: 30 | B40: Receivables | C40: Generate aged receivables report and review balances by donor/partner | D40: Complete | E40: Accountant | G40: HOD | H40: Complete
A41: 31 | B41: Receivables | C41: Follow up on overdue grant reimbursements and donor invoices | D41: N/A | E41: Accountant | G41: HOD | H41: Complete
...

Sheet Summary
A1: Month-End Checklist — Summary
F3: Confirmed by HOD status
A4: Section | B4: Total Items | C4: Complete | D4: Pending / Other | E4: Progress | F4: Complete | G4: Pending / Other | H4: Progress
A5: Income (Statement of Activities) | B5: 6 | C5: =COUNTIF(July!D6:D11,"Complete") -> 6 | D5: =6-C5 -> 0 | E5: =IFERROR(C5/B5,0) -> 1 | F5: =COUNTIF(July!H6:H11,"Complete") -> 6 | G5: =6-F5 -> 0 | H5: =IFERROR(F5/B5,0) -> 1
A6: Expenditure (Statement of Activities) | B6: 7 | C6: =COUNTIF(July!D13:D19,"Complete") -> 3 | D6: =7-C6 -> 4 | E6: =IFERROR(C6/B6,0) -> 0.42857143 | F6: =COUNTIF(July!H13:H19,"Complete") -> 7 | G6: =7-F6 -> 0 | H6: =IFERROR(F6/B6,0) -> 1
A7: Balance Sheet Items | B7: 6 | C7: =COUNTIF(July!D24:D30,"Complete") -> 5 | D7: =6-C7 -> 1 | E7: =IFERROR(C7/B7,0) -> 0.83333333 | F7: =COUNTIF(July!H24:H30,"Complete") -> 7 | G7: =6-F7 -> -1 | H7: =IFERROR(F7/B7,0) -> 1.1666667
A8: Advances | B8: 7 | C8: =COUNTIF(July!D32:D38,"Complete") -> 4 | D8: =7-C8 -> 3 | E8: =IFERROR(C8/B8,0) -> 0.57142857 | F8: =COUNTIF(July!H32:H38,"Complete") -> 7 | G8: =7-F8 -> 0 | H8: =IFERROR(F8/B8,0) -> 1
A9: Receivables | B9: 6 | C9: =COUNTIF(July!D40:D45,"Complete") -> 3 | D9: =6-C9 -> 3 | E9: =IFERROR(C9/B9,0) -> 0.5 | F9: =COUNTIF(July!H40:H45,"Complete") -> 6 | G9: =6-F9 -> 0 | H9: =IFERROR(F9/B9,0) -> 1
A10: Payables | B10: 6 | C10: =COUNTIF(July!D47:D52,"Complete") -> 3 | D10: =6-C10 -> 3 | E10: =IFERROR(C10/B10,0) -> 0.5 | F10: =COUNTIF(July!H47:H52,"Complete") -> 6 | G10: =6-F10 -> 0 | H10: =IFERROR(F10/B10,0) -> 1
A11: Programme & Grants | B11: 6 | C11: =COUNTIF(July!D56:D61,"Complete") -> 2 | D11: =6-C11 -> 4 | E11: =IFERROR(C11/B11,0) -> 0.33333333 | F11: =COUNTIF(July!H56:H61,"Complete") -> 6 | G11: =6-F11 -> 0 | H11: =IFERROR(F11/B11,0) -> 1
A12: Governance & Compliance | B12: 4 | C12: =COUNTIF(July!D64:D67,"Complete") -> 2 | D12: =4-C12 -> 2 | E12: =IFERROR(C12/B12,0) -> 0.5 | F12: =COUNTIF(July!H64:H67,"Complete") -> 4 | G12: =4-F12 -> 0 | H12: =IFERROR(F12/B12,0) -> 1
A13: HR & Operations | B13: 4 | C13: =COUNTIF(July!D69:D69,"Complete") -> 0 | D13: =4-C13 -> 4 | E13: =IFERROR(C13/B13,0) -> 0 | F13: =COUNTIF(July!H69:H69,"Complete") -> 1 | G13: =4-F13 -> 3 | H13: =IFERROR(F13/B13,0) -> 0.25
A14: Archival/filing | B14: 4 | C14: =COUNTIF(July!D70:D70,"Complete") -> 0 | D14: =4-C14 -> 4 | E14: =IFERROR(C14/B14,0) -> 0 | F14: =COUNTIF(July!H70:H70,"Complete") -> 0 | G14: =4-F14 -> 4 | H14: =IFERROR(F14/B14,0) -> 0
A15: TOTAL | B15: =SUM(B5:B14) -> 56 | C15: =SUM(C5:C14) -> 28 | D15: =SUM(D5:D14) -> 28 | E15: =IFERROR(C15/B15,0) -> 0.5 | F15: =SUM(F5:F14) -> 50 | G15: =SUM(G5:G14) -> 6 | H15: =IFERROR(F15/B15,0) -> 0.89285714
