Workbook

Sheet Monthly Checklist
A1: Audit, Accounting & Tax Compliance Firm — Monthly Finance Checklist
A2: Month: _June________ | Prepared by: ___Gregory______ | Date: ___11/7/2026___ | Reviewed by: _______________
A4: # | B4: Category | C4: Sub-Category | D4: Checklist Item | E4: Status | F4: Responsible | G4: Assigned To | H4: Notes | I4: Confirmed by HOD | J4: Status
A5: Billing, Revenue & WIP
A6: 1 | B6: Billing, Revenue & WIP | C6: Timesheet review | D6: Confirm all professional staff have submitted timesheets for every working day of the month | E6: N/A | F6: Accountant | G6: Complete | J6: Pending
A7: 2 | B7: Billing, Revenue & WIP | C7: Timesheet review | D7: Review and approve timesheets; confirm hours are coded to the correct client/engagement | E7: N/A | F7: HOD | G7: Complete | J7: Pending
A8: 3 | B8: Billing, Revenue & WIP | C8: Timesheet review | D8: Identify non-chargeable time (training, admin, BD, leave) and post to correct internal codes | E8: N/A | F8: Accountant | J8: Pending
A9: 4 | B9: Billing, Revenue & WIP | C9: Timesheet review | D9: Reconcile total hours recorded to expected capacity by service line (audit, accounting, tax) | E9: N/A | F9: Accountant | J9: Pending
A10: 5 | B10: Billing, Revenue & WIP | C10: WIP management | D10: Update WIP register for all active audit, accounting, and tax compliance engagements | E10: Complete | F10: Accountant | J10: Pending
A11: 8 | B11: Billing, Revenue & WIP | C11: WIP management | D11: Write down WIP for any engagement where recovery is doubtful; obtain partner approval | E11: Pending | F11: Accountant | J11: Pending
A12: 9 | B12: Billing, Revenue & WIP | C12: Invoice generation | D12: Raise invoices for all completed milestones, monthly retainer fees, and ad hoc work billed this month | E12: Pending | F12: Accountant | J12: Pending
A13: 10 | B13: Billing, Revenue & WIP | C13: Invoice generation | D13: Confirm all invoices are approved by the responsible partner before dispatch to clients | E13: Pending | F13: Accountant | J13: Pending
A14: 11 | B14: Billing, Revenue & WIP | C14: Invoice generation | D14: Confirm invoice amounts, VAT treatment, and client reference agree to the engagement letter | E14: Pending | F14: Accountant | J14: Pending
A15: 12 | B15: Billing, Revenue & WIP | C15: Invoice generation | D15: Issue invoices and record in the billing register against each client and engagement | E15: Pending | F15: Accountant | J15: Pending
A16: 13 | B16: Billing, Revenue & WIP | C16: Revenue recognition | D16: Recognise revenue for work done this month per engagement (% completion or milestone basis) | E16: Pending | F16: Accountant | J16: Pending
A17: 14 | B17: Billing, Revenue & WIP | C17: Revenue recognition | D17: Post deferred income for fees received in advance of work being performed | E17: Pending | F17: Accountant | J17: Pending
A18: 15 | B18: Billing, Revenue & WIP | C18: Revenue recognition | D18: Reconcile recognised revenue to invoices raised and WIP movements for the month | E18: Pending | F18: Accountant | J18: Pending
A19: 16 | B19: Billing, Revenue & WIP | C19: Revenue recognition | D19: Prepare monthly fee income report by service line (audit, accounting, tax compliance) | E19: Pending | F19: Accountant | J19: Pending
A20: Audit Engagements — Monthly Progress
A21: 17 | B21: Audit Engagements — Monthly Progress | C21: Engagement management | D21: Update audit engagement tracker with current status of all active audit assignments | E21: Pending | F21: HOD | J21: Pending
A22: 18 | B22: Audit Engagements — Monthly Progress | C22: Engagement management | D22: Confirm all audit fieldwork scheduled for the month is completed or rescheduled with client agreement | E22: Pending | F22: HOD | J22: Pending
A23: 19 | B23: Audit Engagements — Monthly Progress | C23: Engagement management | D23: Confirm engagement letters are in place for all audits starting this month | E23: Pending | F23: HOD | J23: Pending
A24: 20 | B24: Audit Engagements — Monthly Progress | C24: Engagement management | D24: Confirm audit planning materiality and risk assessments are up to date on active engagements | E24: Pending | F24: Audit Associate | J24: Pending
A25: 21 | B25: Audit Engagements — Monthly Progress | C25: Audit file management | D25: Confirm audit working paper files for all active engagements are being updated and reviewed | E25: Pending | F25: Audit Associate | J25: Pending
A26: 22 | B26: Audit Engagements — Monthly Progress | C26: Audit file management | D26: Confirm all significant audit findings and issues are documented and escalated to partners | E26: Pending | F26: Audit Associate | J26: Pending
A27: 23 | B27: Audit Engagements — Monthly Progress | C27: Audit file management | D27: Confirm outstanding client information requests (PBC lists) are followed up and tracked | E27: Pending | F27: Audit Associate | J27: Pending
A28: 24 | B28: Audit Engagements — Monthly Progress | C28: Audit file management | D28: Confirm all review notes are cleared or carried forward with documented responses | E28: Pending | F28: Audit Associate | J28: Pending
A29: 25 | B29: Audit Engagements — Monthly Progress | C29: Reporting | D29: Confirm all audit reports due for issue this month are completed and issued on time | E29: Pending | F29: Audit Associate | J29: Pending
A30: 26 | B30: Audit Engagements — Monthly Progress | C30: Reporting | D30: Confirm management letters for completed audits are prepared and issued to clients | E30: Pending | F30: Audit Associate | J30: Pending
A31: 27 | B31: Audit Engagements — Monthly Progress | C31: Reporting | D31: Confirm all regulatory submission deadlines (e.g. filing with registrar) for audit clients are met | E31: Pending | F31: Audit Associate | J31: Pending
A32: 28 | B32: Audit Engagements — Monthly Progress | C32: Billing | D32: Confirm audit fee invoices raised match the engagement letter fee schedule or agreed variations | E32: Pending | F32: Audit Associate | J32: Pending
A33: Accounting & Bookkeeping Engagements
A34: 29 | B34: Accounting & Bookkeeping Engagements | C34: Bookkeeping | D34: Confirm all client bookkeeping data (bank statements, invoices, receipts) is received on time | E34: Pending | F34: HOD | J34: Pending
A35: 30 | B35: Accounting & Bookkeeping Engagements | C35: Bookkeeping | D35: Post all client transactions — sales, purchases, payroll, bank — for the month | E35: Pending | F35: Accountant | J35: Pending
A36: 31 | B36: Accounting & Bookkeeping Engagements | C36: Bookkeeping | D36: Reconcile client bank accounts to the cash book for the month | E36: Pending | F36: Accountant | J36: Pending
A37: 32 | B37: Accounting & Bookkeeping Engagements | C37: Bookkeeping | D37: Process client payroll and confirm payroll journals are posted for the month | E37: Pending | F37: Accountant | J37: Pending
A38: 33 | B38: Accounting & Bookkeeping Engagements | C38: Bookkeeping | D38: Confirm all client accounts payable and receivable ledgers are updated and reconciled | E38: Pending | F38: Accountant | J38: Pending
A39: 34 | B39: Accounting & Bookkeeping Engagements | C39: Management accounts | D39: Prepare monthly management accounts for all accounting clients due this month | E39: Pending | F39: HOD | J39: Pending
A40: 35 | B40: Accounting & Bookkeeping Engagements | C40: Management accounts | D40: Confirm management accounts are reviewed by the responsible manager before client delivery | E40: Pending | F40: HOD | J40: Pending
A41: 36 | B41: Accounting & Bookkeeping Engagements | C41: Management accounts | D41: Deliver management accounts to clients within agreed turnaround times | E41: Pending | F41: HOD | J41: Pending
...

Sheet Summary
A1: Monthly Checklist — Summary by Section
G3: Confirmed by HOD status
A4: Section | B4: Sub-categories | C4: Total Items | D4: Complete | E4: Pending / Other | F4: Progress | G4: Complete | H4: Pending / Other | I4: Progress
A5: Billing, Revenue & WIP | B5: 4 | C5: 16 | D5: =COUNTIF('Monthly Checklist'!E6:E19,"Complete") -> 1 | E5: =16-D5 -> 15 | F5: =IFERROR(D5/C5,0) -> 0.0625 | G5: =COUNTIF('Monthly Checklist'!J6:J19,"Complete") -> 0 | H5: =16-G5 -> 16 | I5: =IFERROR(G5/B5,0) -> 0
A6: Audit Engagements — Monthly Progress | B6: 4 | C6: 12 | D6: =COUNTIF('Monthly Checklist'!E21:E32,"Complete") -> 0 | E6: =12-D6 -> 12 | F6: =IFERROR(D6/C6,0) -> 0 | G6: =COUNTIF('Monthly Checklist'!J21:J32,"Complete") -> 0 | H6: =12-G6 -> 12 | I6: =IFERROR(G6/B6,0) -> 0
A7: Accounting & Bookkeeping Engagements | B7: 4 | C7: 13 | D7: =COUNTIF('Monthly Checklist'!E34:E46,"Complete") -> 0 | E7: =13-D7 -> 13 | F7: =IFERROR(D7/C7,0) -> 0 | G7: =COUNTIF('Monthly Checklist'!J34:J46,"Complete") -> 0 | H7: =13-G7 -> 13 | I7: =IFERROR(G7/B7,0) -> 0
A8: Tax Compliance Engagements | B8: 6 | C8: 15 | D8: =COUNTIF('Monthly Checklist'!E48:E57,"Complete") -> 0 | E8: =15-D8 -> 15 | F8: =IFERROR(D8/C8,0) -> 0 | G8: =COUNTIF('Monthly Checklist'!J48:J57,"Complete") -> 0 | H8: =15-G8 -> 15 | I8: =IFERROR(G8/B8,0) -> 0
A9: Cash & Bank | B9: 4 | C9: 16 | D9: =COUNTIF('Monthly Checklist'!E59:E74,"Complete") -> 0 | E9: =16-D9 -> 16 | F9: =IFERROR(D9/C9,0) -> 0 | G9: =COUNTIF('Monthly Checklist'!J59:J74,"Complete") -> 0 | H9: =16-G9 -> 16 | I9: =IFERROR(G9/B9,0) -> 0
A10: Advances | B10: 3 | C10: 8 | D10: =COUNTIF('Monthly Checklist'!E76:E83,"Complete") -> 0 | E10: =8-D10 -> 8 | F10: =IFERROR(D10/C10,0) -> 0 | G10: =COUNTIF('Monthly Checklist'!J76:J83,"Complete") -> 0 | H10: =8-G10 -> 8 | I10: =IFERROR(G10/B10,0) -> 0
A11: Receivables | B11: 4 | C11: 8 | D11: =COUNTIF('Monthly Checklist'!E85:E92,"Complete") -> 0 | E11: =8-D11 -> 8 | F11: =IFERROR(D11/C11,0) -> 0 | G11: =COUNTIF('Monthly Checklist'!J85:J92,"Complete") -> 0 | H11: =8-G11 -> 8 | I11: =IFERROR(G11/B11,0) -> 0
A12: Payables | B12: 4 | C12: 9 | D12: =COUNTIF('Monthly Checklist'!E94:E102,"Complete") -> 0 | E12: =9-D12 -> 9 | F12: =IFERROR(D12/C12,0) -> 0 | G12: =COUNTIF('Monthly Checklist'!J94:J102,"Complete") -> 0 | H12: =9-G12 -> 9 | I12: =IFERROR(G12/B12,0) -> 0
A13: Payroll & Staff Costs | B13: 3 | C13: 9 | D13: =COUNTIF('Monthly Checklist'!E104:E112,"Complete") -> 0 | E13: =9-D13 -> 9 | F13: =IFERROR(D13/C13,0) -> 0 | G13: =COUNTIF('Monthly Checklist'!J104:JH112,"Complete") -> 0 | H13: =9-G13 -> 9 | I13: =IFERROR(G13/B13,0) -> 0
A14: Lock-up, Utilisation & Engagement Profitability | B14: 3 | C14: 8 | D14: =COUNTIF('Monthly Checklist'!E114:E121,"Complete") -> 0 | E14: =8-D14 -> 8 | F14: =IFERROR(D14/C14,0) -> 0 | G14: =COUNTIF('Monthly Checklist'!J114:J121,"Complete") -> 0 | H14: =8-G14 -> 8 | I14: =IFERROR(G14/B14,0) -> 0
A15: Quality Control & Professional Compliance | B15: 4 | C15: 9 | D15: =COUNTIF('Monthly Checklist'!E123:E131,"Complete") -> 0 | E15: =9-D15 -> 9 | F15: =IFERROR(D15/C15,0) -> 0 | G15: =COUNTIF('Monthly Checklist'!J123:J131,"Complete") -> 0 | H15: =9-G15 -> 9 | I15: =IFERROR(G15/B15,0) -> 0
A16: Management Reporting & Governance | B16: 2 | C16: 8 | D16: =COUNTIF('Monthly Checklist'!E133:E140,"Complete") -> 0 | E16: =8-D16 -> 8 | F16: =IFERROR(D16/C16,0) -> 0 | G16: =COUNTIF('Monthly Checklist'!J133:J140,"Complete") -> 0 | H16: =8-G16 -> 8 | I16: =IFERROR(G16/B16,0) -> 0
A17: TOTAL | B17: =SUM(B5:B16) -> 45 | C17: =SUM(C5:C16) -> 131 | D17: =SUM(D5:D16) -> 1 | E17: =SUM(E5:E16) -> 130 | F17: =AVERAGE(F8:F16) -> 0 | G17: =SUM(G5:G16) -> 0 | H17: =SUM(H5:H16) -> 131 | I17: =AVERAGE(I5:I16) -> 0
